<?xml version="1.0"?>
<!-- Revolute-Revolute Manipulator -->
<robot name="diffbot" xmlns:xacro="http://www.ros.org/wiki/xacro">


  <xacro:include filename="$(find diffbot_gazebo)/urdf/ros2_control/diffbot.gazebo.xacro"/>
  <xacro:include filename="$(find diffbot_gazebo)/urdf/ros2_control/diffbot.ros2_control.xacro"/>

  <!-- Chassis -->
  <link name="base_footprint"/>
    

    <joint name="base_joint" type="fixed">
        <parent link="base_footprint"/>
        <child link="base_link"/>
        <origin xyz="0.0 0 0" rpy="0 0 0.0" />
    </joint>

  <link name="base_link">
    <visual>
      <geometry>
        <box size="2.0 1.0 0.5"/>
      </geometry>
      <material name="blue">
        <color rgba="0.0 0.0 1.0 1"/>
      </material>
    </visual>
    <collision>
      <geometry>
        <box size="2.0 1.0 0.5"/>
      </geometry>
    </collision>
    <inertial>
      <mass value="1.14395"/>
      <inertia ixx="0.126164" ixy="0" ixz="0" iyy="0.416519" iyz="0" izz="0.481014"/>
    </inertial>
  </link>

  <!-- Left Wheel -->
  <link name="left_wheel">
    <visual>
      <geometry>
        <cylinder radius="0.4" length="0.2"/>
      </geometry>
      <material name="red">
        <color rgba="1.0 0.0 0.0 1"/>
      </material>
    </visual>
    <collision>
      <geometry>
        <cylinder radius="0.4" length="0.2"/>
      </geometry>
    </collision>
    <inertial>
      <mass value="2.0"/>
      <inertia ixx="0.145833" ixy="0" ixz="0" iyy="0.145833" iyz="0" izz="0.125"/>
    </inertial>
  </link>

  <!-- Right Wheel -->
  <link name="right_wheel">
    <visual>
      <geometry>
        <cylinder radius="0.4" length="0.2"/>
      </geometry>
      <material name="red">
        <color rgba="1.0 0.0 0.0 1"/>
      </material>
    </visual>
    <collision>
      <geometry>
        <cylinder radius="0.4" length="0.2"/>
      </geometry>
    </collision>
    <inertial>
      <mass value="1.0"/>
      <inertia ixx="0.145833" ixy="0" ixz="0" iyy="0.145833" iyz="0" izz="0.125"/>
    </inertial>
  </link>

  <!-- Caster Wheel -->
  <link name="caster">
    <visual>
      <geometry>
        <sphere radius="0.2"/>
      </geometry>
      <material name="green">
        <color rgba="0.0 1.0 0.0 1"/>
      </material>
    </visual>
    <collision>
      <geometry>
        <sphere radius="0.2"/>
      </geometry>
    </collision>
    <inertial>
      <mass value="1.0"/>
      <inertia ixx="0.1" ixy="0" ixz="0" iyy="0.1" iyz="0" izz="0.1"/>
    </inertial>
  </link>

  <!-- depth_cam -->
  <link name="camera_link">
    <visual>
      <geometry>
        <box size="0.2 0.2 0.2"/>
      </geometry>
      <material name="green">
        <color rgba="0.0 1.0 0.0 1"/>
      </material>
    </visual>
    <collision>
      <geometry>
        <box size="0.2 0.2 0.2"/>
      </geometry>
    </collision>
    <inertial>
      <mass value="1.0"/>
      <inertia ixx="0.1" ixy="0" ixz="0" iyy="0.1" iyz="0" izz="0.1"/>
    </inertial>
  </link>


  <!-- lidar -->
  <link name="lidar">
    <visual>
      <geometry>
        <box size="0.2 0.2 0.2"/>
      </geometry>
      <material name="red">
        <color rgba="0.0 1.0 0.0 1"/>
      </material>
    </visual>
    <collision>
      <geometry>
        <box size="0.2 0.2 0.2"/>
      </geometry>
    </collision>
    <inertial>
      <mass value="1.0"/>
      <inertia ixx="0.1" ixy="0" ixz="0" iyy="0.1" iyz="0" izz="0.1"/>
    </inertial>
  </link>


  <!-- imu -->
  <link name="imu">
    <visual>
      <geometry>
        <box size="0.2 0.2 0.2"/>
      </geometry>
      <material name="red">
        <color rgba="1.0 0.0 1.0 1"/>
      </material>
    </visual>
    <collision>
      <geometry>
        <box size="0.2 0.2 0.2"/>
      </geometry>
    </collision>
    <inertial>
      <mass value="1.0"/>
      <inertia ixx="0.1" ixy="0" ixz="0" iyy="0.1" iyz="0" izz="0.1"/>
    </inertial>
  </link>


  <!-- Joints -->
  <joint name="left_wheel_joint" type="continuous">
    <parent link="base_link"/>
    <child link="left_wheel"/>
    <origin xyz="-0.5 0.6 0" rpy="-1.5707 0 0"/>
    <axis xyz="0 0 1"/>
    <dynamics damping="0.02"/>    
  </joint>

  <joint name="right_wheel_joint" type="continuous">
    <parent link="base_link"/>
    <child link="right_wheel"/>
    <origin xyz="-0.5 -0.6 0" rpy="-1.5707 0 0"/>
    <axis xyz="0 0 1"/>
    <dynamics damping="0.02"/>    
  </joint>

  <joint name="caster_joint" type="fixed">
    <parent link="base_link"/>
    <child link="caster"/>
    <origin xyz="0.8 0 -0.2" rpy="0 0 0"/>
  </joint>

  <joint name="depth_joint" type="fixed">
    <parent link="base_link"/>
    <child link="camera_link"/>
    <origin xyz="0.9 0 0.36" rpy="0 0 0"/>
  </joint>

  <joint name="lidar_joint" type="fixed">
    <parent link="base_link"/>
    <child link="lidar"/>
    <origin xyz="0.9 0 0.56" rpy="0 0 0"/>
  </joint>

  <joint name="imu_joint" type="fixed">
    <parent link="base_link"/>
    <child link="imu"/>
    <origin xyz="0.0 0 0.36" rpy="0 0 0"/>
  </joint>


</robot>



